  Running command git clone --quiet https://github.com/huggingface/peft.git /tmp/pip-install-d4nlcq4e/peft_3609244d59984e8c8e94f5ba4b41a41f
  Running command git clone --quiet https://github.com/huggingface/accelerate.git /tmp/pip-install-d4nlcq4e/accelerate_f088421c53db45d0a72f53dbbaab5210
/home/brc4cb/.conda/envs/falcon_40B/lib/python3.9/site-packages/bitsandbytes/cuda_setup/main.py:149: UserWarning: Found duplicate ['libcudart.so', 'libcudart.so.11.0', 'libcudart.so.12.0'] files: {PosixPath('/home/brc4cb/.conda/envs/falcon_40B/lib/libcudart.so'), PosixPath('/home/brc4cb/.conda/envs/falcon_40B/lib/libcudart.so.11.0')}.. We'll flip a coin and try one of these, in order to fail forward.
Either way, this might cause trouble in the future:
If you get `CUDA error: invalid device function` errors, the above might be the cause and the solution is to make sure only one ['libcudart.so', 'libcudart.so.11.0', 'libcudart.so.12.0'] in the paths that we search based on your env.
  warn(msg)
Traceback (most recent call last):
  File "/home/brc4cb/.conda/envs/falcon_40B/lib/python3.9/site-packages/huggingface_hub/utils/_errors.py", line 261, in hf_raise_for_status
    response.raise_for_status()
  File "/home/brc4cb/.conda/envs/falcon_40B/lib/python3.9/site-packages/requests/models.py", line 1021, in raise_for_status
    raise HTTPError(http_error_msg, response=self)
requests.exceptions.HTTPError: 404 Client Error: Not Found for url: https://huggingface.co/meta-llama/Llama-2-70b/resolve/main/config.json

The above exception was the direct cause of the following exception:

Traceback (most recent call last):
  File "/home/brc4cb/.conda/envs/falcon_40B/lib/python3.9/site-packages/transformers/utils/hub.py", line 417, in cached_file
    resolved_file = hf_hub_download(
  File "/home/brc4cb/.conda/envs/falcon_40B/lib/python3.9/site-packages/huggingface_hub/utils/_validators.py", line 118, in _inner_fn
    return fn(*args, **kwargs)
  File "/home/brc4cb/.conda/envs/falcon_40B/lib/python3.9/site-packages/huggingface_hub/file_download.py", line 1195, in hf_hub_download
    metadata = get_hf_file_metadata(
  File "/home/brc4cb/.conda/envs/falcon_40B/lib/python3.9/site-packages/huggingface_hub/utils/_validators.py", line 118, in _inner_fn
    return fn(*args, **kwargs)
  File "/home/brc4cb/.conda/envs/falcon_40B/lib/python3.9/site-packages/huggingface_hub/file_download.py", line 1541, in get_hf_file_metadata
    hf_raise_for_status(r)
  File "/home/brc4cb/.conda/envs/falcon_40B/lib/python3.9/site-packages/huggingface_hub/utils/_errors.py", line 271, in hf_raise_for_status
    raise EntryNotFoundError(message, response) from e
huggingface_hub.utils._errors.EntryNotFoundError: 404 Client Error. (Request ID: Root=1-64c3b7ee-20691819305b9acb70ea5233;0dd2539b-af14-4047-9440-714d793e715a)

Entry Not Found for url: https://huggingface.co/meta-llama/Llama-2-70b/resolve/main/config.json.

During handling of the above exception, another exception occurred:

Traceback (most recent call last):
  File "/gpfs/gpfs0/project/SDS/research/christ_research/Llama 2/llama2-70b/generate_8bit.py", line 63, in <module>
    tokenizer = AutoTokenizer.from_pretrained(model_path, use_auth_token=True)
  File "/home/brc4cb/.conda/envs/falcon_40B/lib/python3.9/site-packages/transformers/models/auto/tokenization_auto.py", line 667, in from_pretrained
    config = AutoConfig.from_pretrained(
  File "/home/brc4cb/.conda/envs/falcon_40B/lib/python3.9/site-packages/transformers/models/auto/configuration_auto.py", line 983, in from_pretrained
    config_dict, unused_kwargs = PretrainedConfig.get_config_dict(pretrained_model_name_or_path, **kwargs)
  File "/home/brc4cb/.conda/envs/falcon_40B/lib/python3.9/site-packages/transformers/configuration_utils.py", line 617, in get_config_dict
    config_dict, kwargs = cls._get_config_dict(pretrained_model_name_or_path, **kwargs)
  File "/home/brc4cb/.conda/envs/falcon_40B/lib/python3.9/site-packages/transformers/configuration_utils.py", line 672, in _get_config_dict
    resolved_config_file = cached_file(
  File "/home/brc4cb/.conda/envs/falcon_40B/lib/python3.9/site-packages/transformers/utils/hub.py", line 463, in cached_file
    raise EnvironmentError(
OSError: meta-llama/Llama-2-70b does not appear to have a file named config.json. Checkout 'https://huggingface.co/meta-llama/Llama-2-70b/main' for available files.
