  Running command git clone --quiet https://github.com/huggingface/transformers.git /tmp/pip-install-m5_po2s3/transformers_7d8509875c9e493abe4a3c5dd1d1426c
  Running command git clone --quiet https://github.com/huggingface/peft.git /tmp/pip-install-m5_po2s3/peft_4a382ae7b302435ba5ba951e45ebff12
  Running command git clone --quiet https://github.com/huggingface/accelerate.git /tmp/pip-install-m5_po2s3/accelerate_2d8ba44a13fd41ee8e9d44257bb8ea33
/home/brc4cb/.conda/envs/falcon_40B/lib/python3.9/site-packages/bitsandbytes/cuda_setup/main.py:149: UserWarning: Found duplicate ['libcudart.so', 'libcudart.so.11.0', 'libcudart.so.12.0'] files: {PosixPath('/home/brc4cb/.conda/envs/falcon_40B/lib/libcudart.so.11.0'), PosixPath('/home/brc4cb/.conda/envs/falcon_40B/lib/libcudart.so')}.. We'll flip a coin and try one of these, in order to fail forward.
Either way, this might cause trouble in the future:
If you get `CUDA error: invalid device function` errors, the above might be the cause and the solution is to make sure only one ['libcudart.so', 'libcudart.so.11.0', 'libcudart.so.12.0'] in the paths that we search based on your env.
  warn(msg)
Traceback (most recent call last):
  File "/home/brc4cb/.conda/envs/falcon_40B/lib/python3.9/site-packages/huggingface_hub/utils/_errors.py", line 261, in hf_raise_for_status
    response.raise_for_status()
  File "/home/brc4cb/.conda/envs/falcon_40B/lib/python3.9/site-packages/requests/models.py", line 1021, in raise_for_status
    raise HTTPError(http_error_msg, response=self)
requests.exceptions.HTTPError: 401 Client Error: Unauthorized for url: https://huggingface.co/meta-llama/Llama-2-70b/resolve/main/config.json

The above exception was the direct cause of the following exception:

Traceback (most recent call last):
  File "/home/brc4cb/.conda/envs/falcon_40B/lib/python3.9/site-packages/transformers/utils/hub.py", line 417, in cached_file
    resolved_file = hf_hub_download(
  File "/home/brc4cb/.conda/envs/falcon_40B/lib/python3.9/site-packages/huggingface_hub/utils/_validators.py", line 118, in _inner_fn
    return fn(*args, **kwargs)
  File "/home/brc4cb/.conda/envs/falcon_40B/lib/python3.9/site-packages/huggingface_hub/file_download.py", line 1195, in hf_hub_download
    metadata = get_hf_file_metadata(
  File "/home/brc4cb/.conda/envs/falcon_40B/lib/python3.9/site-packages/huggingface_hub/utils/_validators.py", line 118, in _inner_fn
    return fn(*args, **kwargs)
  File "/home/brc4cb/.conda/envs/falcon_40B/lib/python3.9/site-packages/huggingface_hub/file_download.py", line 1541, in get_hf_file_metadata
    hf_raise_for_status(r)
  File "/home/brc4cb/.conda/envs/falcon_40B/lib/python3.9/site-packages/huggingface_hub/utils/_errors.py", line 293, in hf_raise_for_status
    raise RepositoryNotFoundError(message, response) from e
huggingface_hub.utils._errors.RepositoryNotFoundError: 401 Client Error. (Request ID: Root=1-64b97abd-6904b17d168f75b233e955de;db4f0565-c036-4325-a86e-3f5f47c292bc)

Repository Not Found for url: https://huggingface.co/meta-llama/Llama-2-70b/resolve/main/config.json.
Please make sure you specified the correct `repo_id` and `repo_type`.
If you are trying to access a private or gated repo, make sure you are authenticated.
Invalid username or password.

During handling of the above exception, another exception occurred:

Traceback (most recent call last):
  File "/gpfs/gpfs0/project/SDS/research/christ_research/Llama 2/llama2-70b/qlora.py", line 813, in <module>
    train()
  File "/gpfs/gpfs0/project/SDS/research/christ_research/Llama 2/llama2-70b/qlora.py", line 649, in train
    model = get_accelerate_model(args, checkpoint_dir)
  File "/gpfs/gpfs0/project/SDS/research/christ_research/Llama 2/llama2-70b/qlora.py", line 286, in get_accelerate_model
    model = AutoModelForCausalLM.from_pretrained(
  File "/home/brc4cb/.conda/envs/falcon_40B/lib/python3.9/site-packages/transformers/models/auto/auto_factory.py", line 461, in from_pretrained
    config, kwargs = AutoConfig.from_pretrained(
  File "/home/brc4cb/.conda/envs/falcon_40B/lib/python3.9/site-packages/transformers/models/auto/configuration_auto.py", line 982, in from_pretrained
    config_dict, unused_kwargs = PretrainedConfig.get_config_dict(pretrained_model_name_or_path, **kwargs)
  File "/home/brc4cb/.conda/envs/falcon_40B/lib/python3.9/site-packages/transformers/configuration_utils.py", line 617, in get_config_dict
    config_dict, kwargs = cls._get_config_dict(pretrained_model_name_or_path, **kwargs)
  File "/home/brc4cb/.conda/envs/falcon_40B/lib/python3.9/site-packages/transformers/configuration_utils.py", line 672, in _get_config_dict
    resolved_config_file = cached_file(
  File "/home/brc4cb/.conda/envs/falcon_40B/lib/python3.9/site-packages/transformers/utils/hub.py", line 433, in cached_file
    raise EnvironmentError(
OSError: meta-llama/Llama-2-70b is not a local folder and is not a valid model identifier listed on 'https://huggingface.co/models'
If this is a private repository, make sure to pass a token having permission to this repo with `use_auth_token` or log in with `huggingface-cli login` and pass `use_auth_token=True`.
