  Running command git clone --quiet https://github.com/huggingface/peft.git /tmp/pip-install-5zmclia5/peft_da9d4211d7434a18a2b207f8e16280a7
  Running command git clone --quiet https://github.com/huggingface/accelerate.git /tmp/pip-install-5zmclia5/accelerate_2d24624f764a448faf71265b6790df14
Traceback (most recent call last):
  File "/home/brc4cb/.conda/envs/falcon_40B/lib/python3.9/site-packages/huggingface_hub/utils/_errors.py", line 261, in hf_raise_for_status
    response.raise_for_status()
  File "/home/brc4cb/.conda/envs/falcon_40B/lib/python3.9/site-packages/requests/models.py", line 1021, in raise_for_status
    raise HTTPError(http_error_msg, response=self)
requests.exceptions.HTTPError: 404 Client Error: Not Found for url: https://huggingface.co/TIGER-Lab/MAmmoTH-70Bf/resolve/main/tokenizer_config.json

The above exception was the direct cause of the following exception:

Traceback (most recent call last):
  File "/home/brc4cb/.conda/envs/falcon_40B/lib/python3.9/site-packages/transformers/utils/hub.py", line 417, in cached_file
    resolved_file = hf_hub_download(
  File "/home/brc4cb/.conda/envs/falcon_40B/lib/python3.9/site-packages/huggingface_hub/utils/_validators.py", line 118, in _inner_fn
    return fn(*args, **kwargs)
  File "/home/brc4cb/.conda/envs/falcon_40B/lib/python3.9/site-packages/huggingface_hub/file_download.py", line 1195, in hf_hub_download
    metadata = get_hf_file_metadata(
  File "/home/brc4cb/.conda/envs/falcon_40B/lib/python3.9/site-packages/huggingface_hub/utils/_validators.py", line 118, in _inner_fn
    return fn(*args, **kwargs)
  File "/home/brc4cb/.conda/envs/falcon_40B/lib/python3.9/site-packages/huggingface_hub/file_download.py", line 1541, in get_hf_file_metadata
    hf_raise_for_status(r)
  File "/home/brc4cb/.conda/envs/falcon_40B/lib/python3.9/site-packages/huggingface_hub/utils/_errors.py", line 293, in hf_raise_for_status
    raise RepositoryNotFoundError(message, response) from e
huggingface_hub.utils._errors.RepositoryNotFoundError: 404 Client Error. (Request ID: Root=1-6504bbad-304470f84e153161142cbc79;14c63b81-33b2-4065-aedc-db6682e1668f)

Repository Not Found for url: https://huggingface.co/TIGER-Lab/MAmmoTH-70Bf/resolve/main/tokenizer_config.json.
Please make sure you specified the correct `repo_id` and `repo_type`.
If you are trying to access a private or gated repo, make sure you are authenticated.

During handling of the above exception, another exception occurred:

Traceback (most recent call last):
  File "/gpfs/gpfs0/project/SDS/research/christ_research/Llama 2/llama2-70b/mammoth_generate.py", line 63, in <module>
    tokenizer = AutoTokenizer.from_pretrained(model_path, use_auth_token=True)
  File "/home/brc4cb/.conda/envs/falcon_40B/lib/python3.9/site-packages/transformers/models/auto/tokenization_auto.py", line 652, in from_pretrained
    tokenizer_config = get_tokenizer_config(pretrained_model_name_or_path, **kwargs)
  File "/home/brc4cb/.conda/envs/falcon_40B/lib/python3.9/site-packages/transformers/models/auto/tokenization_auto.py", line 496, in get_tokenizer_config
    resolved_config_file = cached_file(
  File "/home/brc4cb/.conda/envs/falcon_40B/lib/python3.9/site-packages/transformers/utils/hub.py", line 433, in cached_file
    raise EnvironmentError(
OSError: TIGER-Lab/MAmmoTH-70Bf is not a local folder and is not a valid model identifier listed on 'https://huggingface.co/models'
If this is a private repository, make sure to pass a token having permission to this repo with `use_auth_token` or log in with `huggingface-cli login` and pass `use_auth_token=True`.
