  Running command git clone --quiet https://github.com/huggingface/peft.git /tmp/pip-install-ytsf2prg/peft_607d22d5138f49b9843a544439b5b6a8
  Running command git clone --quiet https://github.com/huggingface/accelerate.git /tmp/pip-install-ytsf2prg/accelerate_112267c740aa4b2fae76a947d8336bfb
/home/brc4cb/.conda/envs/falcon_40B/lib/python3.9/site-packages/bitsandbytes/cuda_setup/main.py:149: UserWarning: Found duplicate ['libcudart.so', 'libcudart.so.11.0', 'libcudart.so.12.0'] files: {PosixPath('/home/brc4cb/.conda/envs/falcon_40B/lib/libcudart.so.11.0'), PosixPath('/home/brc4cb/.conda/envs/falcon_40B/lib/libcudart.so')}.. We'll flip a coin and try one of these, in order to fail forward.
Either way, this might cause trouble in the future:
If you get `CUDA error: invalid device function` errors, the above might be the cause and the solution is to make sure only one ['libcudart.so', 'libcudart.so.11.0', 'libcudart.so.12.0'] in the paths that we search based on your env.
  warn(msg)
Found cached dataset csv (/home/brc4cb/.cache/huggingface/datasets/csv/default-10416fda93fda02b/0.0.0/eea64c71ca8b46dd3f537ed218fc9bf495d5707789152eb2764f5c78fa66d59d)
  0%|          | 0/1 [00:00<?, ?it/s]100%|██████████| 1/1 [00:00<00:00, 504.12it/s]
Traceback (most recent call last):
  File "/gpfs/gpfs0/project/SDS/research/christ_research/Llama 2/llama2-70b/text_classifier.py", line 66, in <module>
    train_test_valid_dataset = dataset.copy().shuffle()
AttributeError: 'dict' object has no attribute 'shuffle'
