  Running command git clone --quiet https://github.com/huggingface/peft.git /tmp/pip-install-ik_7bqg6/peft_8b71827f092248be995f5317300573fe
  Running command git clone --quiet https://github.com/huggingface/accelerate.git /tmp/pip-install-ik_7bqg6/accelerate_1330b82fccc04dbbb8e7ead2eadf7f92
Traceback (most recent call last):
  File "/home/brc4cb/.conda/envs/falcon_40B/lib/python3.9/site-packages/transformers/utils/import_utils.py", line 1099, in _get_module
    return importlib.import_module("." + module_name, self.__name__)
  File "/home/brc4cb/.conda/envs/falcon_40B/lib/python3.9/importlib/__init__.py", line 127, in import_module
    return _bootstrap._gcd_import(name[level:], package, level)
  File "<frozen importlib._bootstrap>", line 1030, in _gcd_import
  File "<frozen importlib._bootstrap>", line 1007, in _find_and_load
  File "<frozen importlib._bootstrap>", line 986, in _find_and_load_unlocked
  File "<frozen importlib._bootstrap>", line 680, in _load_unlocked
  File "<frozen importlib._bootstrap_external>", line 850, in exec_module
  File "<frozen importlib._bootstrap>", line 228, in _call_with_frames_removed
  File "/home/brc4cb/.conda/envs/falcon_40B/lib/python3.9/site-packages/transformers/trainer_seq2seq.py", line 23, in <module>
    from .deepspeed import is_deepspeed_zero3_enabled
  File "/home/brc4cb/.conda/envs/falcon_40B/lib/python3.9/site-packages/transformers/deepspeed.py", line 37, in <module>
    from accelerate.utils.deepspeed import HfDeepSpeedConfig as DeepSpeedConfig
  File "/home/brc4cb/.conda/envs/falcon_40B/lib/python3.9/site-packages/accelerate/__init__.py", line 3, in <module>
    from .accelerator import Accelerator
  File "/home/brc4cb/.conda/envs/falcon_40B/lib/python3.9/site-packages/accelerate/accelerator.py", line 35, in <module>
    from .checkpointing import load_accelerator_state, load_custom_state, save_accelerator_state, save_custom_state
  File "/home/brc4cb/.conda/envs/falcon_40B/lib/python3.9/site-packages/accelerate/checkpointing.py", line 24, in <module>
    from .utils import (
  File "/home/brc4cb/.conda/envs/falcon_40B/lib/python3.9/site-packages/accelerate/utils/__init__.py", line 131, in <module>
    from .bnb import has_4bit_bnb_layers, load_and_quantize_model
  File "/home/brc4cb/.conda/envs/falcon_40B/lib/python3.9/site-packages/accelerate/utils/bnb.py", line 42, in <module>
    import bitsandbytes as bnb
  File "/home/brc4cb/.conda/envs/falcon_40B/lib/python3.9/site-packages/bitsandbytes/__init__.py", line 16, in <module>
    from .nn import modules
  File "/home/brc4cb/.conda/envs/falcon_40B/lib/python3.9/site-packages/bitsandbytes/nn/__init__.py", line 6, in <module>
    from .triton_based_modules import SwitchBackLinear, SwitchBackLinearGlobal, SwitchBackLinearVectorwise, StandardLinear
  File "/home/brc4cb/.conda/envs/falcon_40B/lib/python3.9/site-packages/bitsandbytes/nn/triton_based_modules.py", line 8, in <module>
    from bitsandbytes.triton.dequantize_rowwise import dequantize_rowwise
  File "/home/brc4cb/.conda/envs/falcon_40B/lib/python3.9/site-packages/bitsandbytes/triton/dequantize_rowwise.py", line 10, in <module>
    import triton
  File "/home/brc4cb/.conda/envs/falcon_40B/lib/python3.9/site-packages/triton/__init__.py", line 20, in <module>
    from .runtime import (
  File "/home/brc4cb/.conda/envs/falcon_40B/lib/python3.9/site-packages/triton/runtime/__init__.py", line 1, in <module>
    from .autotuner import Config, Heuristics, autotune, heuristics
  File "/home/brc4cb/.conda/envs/falcon_40B/lib/python3.9/site-packages/triton/runtime/autotuner.py", line 7, in <module>
    from ..compiler import OutOfResources
  File "/home/brc4cb/.conda/envs/falcon_40B/lib/python3.9/site-packages/triton/compiler/__init__.py", line 1, in <module>
    from .compiler import CompiledKernel, compile
  File "/home/brc4cb/.conda/envs/falcon_40B/lib/python3.9/site-packages/triton/compiler/compiler.py", line 18, in <module>
    from ..runtime.autotuner import OutOfResources
ImportError: cannot import name 'OutOfResources' from partially initialized module 'triton.runtime.autotuner' (most likely due to a circular import) (/home/brc4cb/.conda/envs/falcon_40B/lib/python3.9/site-packages/triton/runtime/autotuner.py)

The above exception was the direct cause of the following exception:

Traceback (most recent call last):
  File "/gpfs/gpfs0/project/SDS/research/christ_research/Llama 2/llama2-70b/text_classifier.py", line 23, in <module>
    from transformers import (
  File "<frozen importlib._bootstrap>", line 1055, in _handle_fromlist
  File "/home/brc4cb/.conda/envs/falcon_40B/lib/python3.9/site-packages/transformers/utils/import_utils.py", line 1089, in __getattr__
    module = self._get_module(self._class_to_module[name])
  File "/home/brc4cb/.conda/envs/falcon_40B/lib/python3.9/site-packages/transformers/utils/import_utils.py", line 1101, in _get_module
    raise RuntimeError(
RuntimeError: Failed to import transformers.trainer_seq2seq because of the following error (look up to see its traceback):
cannot import name 'OutOfResources' from partially initialized module 'triton.runtime.autotuner' (most likely due to a circular import) (/home/brc4cb/.conda/envs/falcon_40B/lib/python3.9/site-packages/triton/runtime/autotuner.py)
